<?xml version="1.0" ?>
<!-- =================================================================================== -->
<!-- |    This document was autogenerated by xacro from spot.urdf.xacro                | -->
<!-- |    EDITING THIS FILE BY HAND IS NOT RECOMMENDED                                 | -->
<!-- =================================================================================== -->
<robot name="spot">
  <link name="base">
    <visual>
      <origin rpy="0 0 0" xyz="0 0 0"/>
      <geometry>
        <mesh filename="file:///home/kuba/fun/ros/spot/src/spot/spot_description/meshes/visual/body.dae"/>
      </geometry>
    </visual>
    <collision>
      <geometry>
        <box size="0.7 0.3 0.2"/>
      </geometry>
    </collision>
  </link>
  <link name="base_inertia">
    <inertial>
      <origin rpy="0.0 0.0 0.0" xyz="0.006394396536052227 -9.812158532440662e-05 0.0009113792330026627"/>
      <mass value="32.86"/>
      <inertia ixx="0.13143999874591827" ixy="0.0" ixz="0.0" iyy="0.13143999874591827" iyz="0.0" izz="0.13143999874591827"/>
    </inertial>
  </link>
  <joint name="body_inertia_joint" type="fixed">
    <origin rpy="0 0 0" xyz="0 0 0"/>
    <parent link="base"/>
    <child link="base_inertia"/>
  </joint>
  <link name="fl_hip">
    <visual>
      <origin rpy="0 0 0" xyz="0 0 0"/>
      <geometry>
        <mesh filename="file:///home/kuba/fun/ros/spot/src/spot/spot_description/meshes/visual/fl_hip.dae"/>
      </geometry>
    </visual>
    <inertial>
      <origin rpy="-0.716521349312305 0.02956473059648479 0.03655230014702582" xyz="-0.005374345928430557 0.012841847725212574 9.875232353806496e-05"/>
      <mass value="1.68"/>
      <inertia ixx="0.0021147398873455382" ixy="0.0" ixz="0.0" iyy="0.0018129577956607131" iyz="0.0" izz="0.002265435737304666"/>
    </inertial>
  </link>
  <joint name="LF_HAA" type="revolute">
    <origin rpy="0 0 0" xyz="0.29785 0.05500 0.00000"/>
    <axis xyz="1 0 0"/>
    <parent link="base"/>
    <child link="fl_hip"/>
    <limit effort="1000" lower="-10.78539816339744827899" upper="10.78539816339744827899" velocity="1000.00"/>
  </joint>
  <link name="fl_uleg">
    <visual>
      <origin rpy="0 0 0" xyz="0 0 0"/>
      <geometry>
        <mesh filename="file:///home/kuba/fun/ros/spot/src/spot/spot_description/meshes/visual/fl_uleg.dae"/>
      </geometry>
      <material name="fl_uleg">
        <color rgba="1 0.8431 0 1"/>
      </material>
    </visual>
    <inertial>
      <origin rpy="-0.26437828203369795 -0.04853174570753804 0.024046963096353124" xyz="0.005142373498529196 -0.0024323679972440004 -0.12100915610790253"/>
      <mass value="2.34"/>
      <inertia ixx="0.02755964961185679" ixy="0.0" ixz="0.0" iyy="0.027354914287651046" iyz="0.0" izz="0.002848145546743553"/>
    </inertial>
  </link>
  <joint name="LF_HFE" type="revolute">
    <origin rpy="0 0 0" xyz="0.0 0.11080 0.0"/>
    <axis xyz="0 1      0"/>
    <parent link="fl_hip"/>
    <child link="fl_uleg"/>
    <limit effort="1000" lower="-10.89884456477707963539" upper="12.2951079663725435509" velocity="1000.00"/>
  </joint>
  <link name="fl_lleg">
    <visual>
      <origin rpy="0 0 0" xyz="0 0 0"/>
      <geometry>
        <mesh filename="file:///home/kuba/fun/ros/spot/src/spot/spot_description/meshes/visual/fl_lleg.dae"/>
      </geometry>
    </visual>
    .
    
    <collision name="LF_FOOT_collision_sensor">
      <origin rpy="0 0 0" xyz="0 0 -0.335"/>
      <geometry>
        <sphere radius="0.035"/>
      </geometry>
    </collision>
    <inertial>
      <origin rpy="-0.007266925694167092 -0.009591807116834161 0.00035255970529224356" xyz="0.00225794012658298 4.607596201822162e-05 -0.1800822913646698"/>
      <mass value="0.35"/>
      <inertia ixx="0.003999022654901177" ixy="0.0" ixz="0.0" iyy="0.0040503157598010785" iyz="0.0" izz="0.0001493402097647426"/>
    </inertial>
  </link>
  <joint name="LF_KFE" type="revolute">
    <origin rpy="0 0 0" xyz="0.025 0.000 -0.3200"/>
    <axis xyz="0 1 0"/>
    <parent link="fl_uleg"/>
    <child link="fl_lleg"/>
    <limit effort="1000" lower="12.7929" upper="-12.7929" velocity="1000.00"/>
  </joint>
  <link name="LF_FOOT"/>
  <joint name="LF_FOOT_JOINT" type="fixed">
    <origin rpy="0 0 0" xyz="0.0 0.0 -0.335"/>
    <parent link="fl_lleg"/>
    <child link="LF_FOOT"/>
    \
  
  </joint>
  <link name="fr_hip">
    <visual>
      <origin rpy="0 0 0" xyz="0 0 0"/>
      <geometry>
        <mesh filename="file:///home/kuba/fun/ros/spot/src/spot/spot_description/meshes/visual/fr_hip.dae"/>
      </geometry>
      <material name="fr_hip">
        <color rgba="0.2 0.2 0.2 1"/>
      </material>
    </visual>
    <inertial>
      <origin rpy="0.7165213493123055 -0.02956473059648479 0.03655230014702582" xyz="-0.005374345928430557 -0.012841847725212574 -9.875232353806496e-05"/>
      <mass value="1.68"/>
      <inertia ixx="0.0021147398873455382" ixy="0.0" ixz="0.0" iyy="0.0018129577956607131" iyz="0.0" izz="0.002265435737304666"/>
    </inertial>
  </link>
  <joint name="RF_HAA" type="revolute">
    <origin rpy="0 0 0" xyz="0.29785 -0.05500 0.00000"/>
    <axis xyz="1 0 0"/>
    <parent link="base"/>
    <child link="fr_hip"/>
    <limit effort="1000" lower="-10.78539816339744827899" upper="10.78539816339744827899" velocity="1000.00"/>
  </joint>
  <link name="fr_uleg">
    <visual>
      <origin rpy="0 0 0" xyz="0 0 0"/>
      <geometry>
        <mesh filename="file:///home/kuba/fun/ros/spot/src/spot/spot_description/meshes/visual/fr_uleg.dae"/>
      </geometry>
      <material name="fr_uleg">
        <color rgba="1 0.8431 0 1"/>
      </material>
    </visual>
    <inertial>
      <origin rpy="0.2643905306958363 -0.04853174688302708 -0.024046943559834943" xyz="0.005142373498529196 0.0024323677644133568 -0.12100915610790253"/>
      <mass value="2.34"/>
      <inertia ixx="0.02755964678927691" ixy="0.0" ixz="0.0" iyy="0.02735491706466737" iyz="0.0" izz="0.0028481453594764797"/>
    </inertial>
  </link>
  <joint name="RF_HFE" type="revolute">
    <origin rpy="0 0 0" xyz="0.0 -0.11080 0.0"/>
    <axis xyz="0  1      0"/>
    <parent link="fr_hip"/>
    <child link="fr_uleg"/>
    <limit effort="1000" lower="-10.898845" upper="12.24363" velocity="1000.00"/>
  </joint>
  <link name="fr_lleg">
    <visual>
      <origin rpy="0 0 0" xyz="0 0 0"/>
      <geometry>
        <mesh filename="file:///home/kuba/fun/ros/spot/src/spot/spot_description/meshes/visual/fr_lleg.dae"/>
      </geometry>
    </visual>
    <collision name="RF_FOOT_collision_sensor">
      <origin rpy="0 0 0" xyz="0 0 -0.335"/>
      <geometry>
        <sphere radius="0.035"/>
      </geometry>
    </collision>
    <inertial>
      <origin rpy="-0.007266925694167092 -0.009591807116834161 0.00035255970529224356" xyz="0.00225794012658298 4.607596201822162e-05 -0.1800822913646698"/>
      <mass value="0.35"/>
      <inertia ixx="0.003999022654901177" ixy="0.0" ixz="0.0" iyy="0.0040503157598010785" iyz="0.0" izz="0.0001493402097647426"/>
    </inertial>
  </link>
  <joint name="RF_KFE" type="revolute">
    <origin rpy="0 0 0" xyz="0.025 0.000 -0.3200"/>
    <axis xyz="0 1 0"/>
    <parent link="fr_uleg"/>
    <child link="fr_lleg"/>
    <limit effort="1000" lower="12.7929" upper="-12.7929" velocity="1000.00"/>
  </joint>
  <link name="RF_FOOT"/>
  <joint name="RF_FOOT_JOINT" type="fixed">
    <origin rpy="0 0 0" xyz="0.0 0.0 -0.335"/>
    <parent link="fr_lleg"/>
    <child link="RF_FOOT"/>
  </joint>
  <link name="hl_hip">
    <visual>
      <origin rpy="0 0 0" xyz="0 0 0"/>
      <geometry>
        <mesh filename="file:///home/kuba/fun/ros/spot/src/spot/spot_description/meshes/visual/hl_hip.dae"/>
      </geometry>
      <material name="hl_hip">
        <color rgba="0.2 0.2 0.2 1"/>
      </material>
    </visual>
    <inertial>
      <origin rpy="0.7165213493123055 0.02956473059648479 -0.03655230014702582" xyz="0.005374345928430557 0.012841847725212574 -9.875232353806496e-05"/>
      <mass value="1.68"/>
      <inertia ixx="0.0021147398873455382" ixy="0.0" ixz="0.0" iyy="0.0018129577956607131" iyz="0.0" izz="0.002265435737304666"/>
    </inertial>
  </link>
  <joint name="LH_HAA" type="revolute">
    <origin rpy="0 0 0" xyz="-0.29785 0.05500 0.00000"/>
    <axis xyz="1 0 0"/>
    <parent link="base"/>
    <child link="hl_hip"/>
    <limit effort="1000" lower="-10.78539816339744827899" upper="10.78539816339744827899" velocity="1000.00"/>
  </joint>
  <link name="hl_uleg">
    <visual>
      <origin rpy="0 0 0" xyz="0 0 0"/>
      <geometry>
        <mesh filename="file:///home/kuba/fun/ros/spot/src/spot/spot_description/meshes/visual/hl_uleg.dae"/>
      </geometry>
      <material name="hl_uleg">
        <color rgba="1 0.8431 0 1"/>
      </material>
    </visual>
    <inertial>
      <origin rpy="-0.26437828203369795 -0.04853174570753804 0.024046963096353124" xyz="0.005142373498529196 -0.0024323679972440004 -0.12100915610790253"/>
      <mass value="2.34"/>
      <inertia ixx="0.02755964961185679" ixy="0.0" ixz="0.0" iyy="0.027354914287651046" iyz="0.0" izz="0.002848145546743553"/>
    </inertial>
  </link>
  <joint name="LH_HFE" type="revolute">
    <origin rpy="0 0 0" xyz="0.0 0.11080 0.0"/>
    <axis xyz="0 1      0"/>
    <parent link="hl_hip"/>
    <child link="hl_uleg"/>
    <limit effort="1000" lower="-10.89884456477707963539" upper="12.2951079663725435509" velocity="1000.00"/>
  </joint>
  <link name="hl_lleg">
    <visual>
      <origin rpy="0 0 0" xyz="0 0 0"/>
      <geometry>
        <mesh filename="file:///home/kuba/fun/ros/spot/src/spot/spot_description/meshes/visual/hl_lleg.dae"/>
      </geometry>
    </visual>
    <collision name="LH_FOOT_collision_sensor">
      <origin rpy="0 0 0" xyz="0 0 -0.335"/>
      <geometry>
        <sphere radius="0.035"/>
      </geometry>
    </collision>
    <inertial>
      <origin rpy="-0.007266925694167092 -0.009591807116834161 0.00035255970529224356" xyz="0.00225794012658298 4.607596201822162e-05 -0.1800822913646698"/>
      <mass value="0.35"/>
      <inertia ixx="0.003999022654901177" ixy="0.0" ixz="0.0" iyy="0.0040503157598010785" iyz="0.0" izz="0.0001493402097647426"/>
    </inertial>
  </link>
  <joint name="LH_KFE" type="revolute">
    <origin rpy="0 0 0" xyz="0.025 0.000 -0.3200"/>
    <axis xyz="0 1 0"/>
    <parent link="hl_uleg"/>
    <child link="hl_lleg"/>
    <limit effort="1000" lower="12.7929" upper="-12.7929" velocity="1000.00"/>
  </joint>
  <link name="LH_FOOT"/>
  <joint name="LH_FOOT_JOINT" type="fixed">
    <origin rpy="0 0 0" xyz="0.0 0.0 -0.335"/>
    <parent link="hl_lleg"/>
    <child link="LH_FOOT"/>
  </joint>
  <link name="hr_hip">
    <visual>
      <origin rpy="0 0 0" xyz="0 0 0"/>
      <geometry>
        <mesh filename="file:///home/kuba/fun/ros/spot/src/spot/spot_description/meshes/visual/hr_hip.dae"/>
      </geometry>
      <material name="hr_hip">
        <color rgba="0.2 0.2 0.2 1"/>
      </material>
    </visual>
    <inertial>
      <origin rpy="-0.716521349312305 -0.02956473059648479 -0.03655230014702582" xyz="0.005374345928430557 -0.012841847725212574 9.875232353806496e-05"/>
      <mass value="1.68"/>
      <inertia ixx="0.0021147398873455382" ixy="0.0" ixz="0.0" iyy="0.0018129577956607131" iyz="0.0" izz="0.002265435737304666"/>
    </inertial>
  </link>
  <joint name="RH_HAA" type="revolute">
    <origin rpy="0 0 0" xyz="-0.29785 -0.05500 0.00000"/>
    <axis xyz="1 0 0"/>
    <parent link="base"/>
    <child link="hr_hip"/>
    <limit effort="1000" lower="-10.78539816339744827899" upper="10.78539816339744827899" velocity="1000.00"/>
  </joint>
  <link name="hr_uleg">
    <visual>
      <origin rpy="0 0 0" xyz="0 0 0"/>
      <geometry>
        <mesh filename="file:///home/kuba/fun/ros/spot/src/spot/spot_description/meshes/visual/hr_uleg.dae"/>
      </geometry>
      <material name="hr_uleg">
        <color rgba="1 0.8431 0 1"/>
      </material>
    </visual>
    <inertial>
      <origin rpy="0.2643905306958363 -0.04853174688302708 -0.024046943559834943" xyz="0.005142373498529196 0.0024323677644133568 -0.12100915610790253"/>
      <mass value="2.34"/>
      <inertia ixx="0.02755964678927691" ixy="0.0" ixz="0.0" iyy="0.02735491706466737" iyz="0.0" izz="0.0028481453594764797"/>
    </inertial>
  </link>
  <joint name="RH_HFE" type="revolute">
    <origin rpy="0 0 0" xyz="0.0 -0.11080 0.0"/>
    <axis xyz="0  1      0"/>
    <parent link="hr_hip"/>
    <child link="hr_uleg"/>
    <limit effort="1000" lower="-10.89884456477707963539" upper="12.2951079663725435509" velocity="1000.00"/>
  </joint>
  <link name="hr_lleg">
    <visual>
      <origin rpy="0 0 0" xyz="0 0 0"/>
      <geometry>
        <mesh filename="file:///home/kuba/fun/ros/spot/src/spot/spot_description/meshes/visual/hr_lleg.dae"/>
      </geometry>
    </visual>
    <collision name="RH_FOOT_collision_sensor">
      <origin rpy="0 0 0" xyz="0 0 -0.335"/>
      <geometry>
        <sphere radius="0.035"/>
      </geometry>
    </collision>
    <inertial>
      <origin rpy="-0.007266925694167092 -0.009591807116834161 0.00035255970529224356" xyz="0.00225794012658298 4.607596201822162e-05 -0.1800822913646698"/>
      <mass value="0.35"/>
      <inertia ixx="0.003999022654901177" ixy="0.0" ixz="0.0" iyy="0.0040503157598010785" iyz="0.0" izz="0.0001493402097647426"/>
    </inertial>
  </link>
  <joint name="RH_KFE" type="revolute">
    <origin rpy="0 0 0" xyz="0.025 0.000 -0.3200"/>
    <axis xyz="0 1 0"/>
    <parent link="hr_uleg"/>
    <child link="hr_lleg"/>
    <limit effort="1000" lower="12.7929" upper="-12.7929" velocity="1000.00"/>
  </joint>
  <link name="RH_FOOT"/>
  <joint name="RH_FOOT_JOINT" type="fixed">
    <origin rpy="0 0 0" xyz="0.0 0.0 -0.335"/>
    <parent link="hr_lleg"/>
    <child link="RH_FOOT"/>
  </joint>
  <!-- Standard accessories. -->
  <!-- <xacro:include filename="$(find spot_description)/urdf/accessories.urdf.xacro" /> -->
  <!-- Optional custom includes. -->
  <!-- <xacro:include filename="$(optenv SPOT_URDF_EXTRAS empty.urdf)" /> -->
  <gazebo reference="LF_FOOT">
    <mu1>1.85</mu1>
    <mu2>1.85</mu2>
    <kp value="1000000.0"/>
    <kd value="1.0"/>
  </gazebo>
  <gazebo reference="RF_FOOT">
    <mu1>1.85</mu1>
    <mu2>1.85</mu2>
    <kp value="1000000.0"/>
    <kd value="1.0"/>
  </gazebo>
  <gazebo reference="LH_FOOT">
    <mu1>1.85</mu1>
    <mu2>1.85</mu2>
    <kp value="1000000.0"/>
    <kd value="1.0"/>
  </gazebo>
  <gazebo reference="RH_FOOT">
    <mu1>1.85</mu1>
    <mu2>1.85</mu2>
    <kp value="1000000.0"/>
    <kd value="1.0"/>
  </gazebo>
  <gazebo>
    <plugin filename="libgazebo_ros_control.so" name="gazebo_ros_control">
      <robotSimType>gazebo_ros_control/DefaultRobotHWSim</robotSimType>
      <robotNamespace>/anymal</robotNamespace>
    </plugin>
    <plugin filename="libStateEstimator.so" name="StateEstimator"/>
  </gazebo>
  <transmission name="transmission_0">
    <type>transmission_interface/SimpleTransmission</type>
    <joint name="LF_HAA">
      <hardwareInterface>hardware_interface/EffortJointInterface</hardwareInterface>
    </joint>
    <actuator name="motor_0">
      <hardwareInterface>EffortJointInterface</hardwareInterface>
      <mechanicalReduction>1</mechanicalReduction>
    </actuator>
  </transmission>
  <transmission name="transmission_1">
    <type>transmission_interface/SimpleTransmission</type>
    <joint name="LF_HFE">
      <hardwareInterface>hardware_interface/EffortJointInterface</hardwareInterface>
    </joint>
    <actuator name="motor_1">
      <hardwareInterface>EffortJointInterface</hardwareInterface>
      <mechanicalReduction>1</mechanicalReduction>
    </actuator>
  </transmission>
  <transmission name="transmission_2">
    <type>transmission_interface/SimpleTransmission</type>
    <joint name="LF_KFE">
      <hardwareInterface>hardware_interface/EffortJointInterface</hardwareInterface>
    </joint>
    <actuator name="motor_2">
      <hardwareInterface>EffortJointInterface</hardwareInterface>
      <mechanicalReduction>1</mechanicalReduction>
    </actuator>
  </transmission>
  <transmission name="transmission_0dasd">
    <type>transmission_interface/SimpleTransmission</type>
    <joint name="RF_HAA">
      <hardwareInterface>hardware_interface/EffortJointInterface</hardwareInterface>
    </joint>
    <actuator name="motor_0dasd">
      <hardwareInterface>EffortJointInterface</hardwareInterface>
      <mechanicalReduction>1</mechanicalReduction>
    </actuator>
  </transmission>
  <transmission name="transmission_3">
    <type>transmission_interface/SimpleTransmission</type>
    <joint name="RF_HFE">
      <hardwareInterface>hardware_interface/EffortJointInterface</hardwareInterface>
    </joint>
    <actuator name="motor_3">
      <hardwareInterface>EffortJointInterface</hardwareInterface>
      <mechanicalReduction>1</mechanicalReduction>
    </actuator>
  </transmission>
  <transmission name="transmission_4">
    <type>transmission_interface/SimpleTransmission</type>
    <joint name="RF_KFE">
      <hardwareInterface>hardware_interface/EffortJointInterface</hardwareInterface>
    </joint>
    <actuator name="motor_4">
      <hardwareInterface>EffortJointInterface</hardwareInterface>
      <mechanicalReduction>1</mechanicalReduction>
    </actuator>
  </transmission>
  <transmission name="transmission_5">
    <type>transmission_interface/SimpleTransmission</type>
    <joint name="LH_HAA">
      <hardwareInterface>hardware_interface/EffortJointInterface</hardwareInterface>
    </joint>
    <actuator name="motor_5">
      <hardwareInterface>EffortJointInterface</hardwareInterface>
      <mechanicalReduction>1</mechanicalReduction>
    </actuator>
  </transmission>
  <transmission name="transmission_6">
    <type>transmission_interface/SimpleTransmission</type>
    <joint name="LH_HFE">
      <hardwareInterface>hardware_interface/EffortJointInterface</hardwareInterface>
    </joint>
    <actuator name="motor_61">
      <hardwareInterface>EffortJointInterface</hardwareInterface>
      <mechanicalReduction>1</mechanicalReduction>
    </actuator>
  </transmission>
  <transmission name="transmission_2hh">
    <type>transmission_interface/SimpleTransmission</type>
    <joint name="LH_KFE">
      <hardwareInterface>hardware_interface/EffortJointInterface</hardwareInterface>
    </joint>
    <actuator name="motor_2hh">
      <hardwareInterface>EffortJointInterface</hardwareInterface>
      <mechanicalReduction>1</mechanicalReduction>
    </actuator>
  </transmission>
  <transmission name="transmission_0dasdfdsfds">
    <type>transmission_interface/SimpleTransmission</type>
    <joint name="RH_HAA">
      <hardwareInterface>hardware_interface/EffortJointInterface</hardwareInterface>
    </joint>
    <actuator name="motor_0dasdssss">
      <hardwareInterface>EffortJointInterface</hardwareInterface>
      <mechanicalReduction>1</mechanicalReduction>
    </actuator>
  </transmission>
  <transmission name="transmission_332">
    <type>transmission_interface/SimpleTransmission</type>
    <joint name="RH_HFE">
      <hardwareInterface>hardware_interface/EffortJointInterface</hardwareInterface>
    </joint>
    <actuator name="motor_332">
      <hardwareInterface>EffortJointInterface</hardwareInterface>
      <mechanicalReduction>1</mechanicalReduction>
    </actuator>
  </transmission>
  <transmission name="transmission_4fsdfsa121">
    <type>transmission_interface/SimpleTransmission</type>
    <joint name="RH_KFE">
      <hardwareInterface>hardware_interface/EffortJointInterface</hardwareInterface>
    </joint>
    <actuator name="motor_4fsdfsdfdsf">
      <hardwareInterface>EffortJointInterface</hardwareInterface>
      <mechanicalReduction>1</mechanicalReduction>
    </actuator>
  </transmission>
  <gazebo reference="LF_FOOT">
    <sensor name="lf_foot_contact" type="contact">
      <plugin filename="libContactSensor.so" name="lf_contact_plugin"/>
      <contact>
        <collision>fl_lleg_fixed_joint_lump__LF_FOOT_collision_sensor_collision</collision>
      </contact>
    </sensor>
  </gazebo>
  <gazebo reference="LH_FOOT">
    <sensor name="lh_foot_contact" type="contact">
      <plugin filename="libContactSensor.so" name="lh_contact_plugin"/>
      <contact>
        <collision>hl_lleg_fixed_joint_lump__LH_FOOT_collision_sensor_collision</collision>
      </contact>
    </sensor>
  </gazebo>
  <gazebo reference="RF_FOOT">
    <sensor name="rf_foot_contact" type="contact">
      <plugin filename="libContactSensor.so" name="rf_contact_plugin"/>
      <contact>
        <collision>fr_lleg_fixed_joint_lump__RF_FOOT_collision_sensor_collision</collision>
      </contact>
    </sensor>
  </gazebo>
  <gazebo reference="RH_FOOT">
    <sensor name="rh_foot_contact" type="contact">
      <plugin filename="libContactSensor.so" name="rh_contact_plugin"/>
      <contact>
        <collision>hr_lleg_fixed_joint_lump__RH_FOOT_collision_sensor_collision</collision>
      </contact>
    </sensor>
  </gazebo>
</robot>

