<sdf version='1.7'>
  <model name='spot'>
    <link name='base'>
      <inertial>
        <pose>0.006394 -9.8e-05 0.000911 0 -0 0</pose>
        <mass>32.86</mass>
        <inertia>
          <ixx>0.13144</ixx>
          <ixy>0</ixy>
          <ixz>0</ixz>
          <iyy>0.13144</iyy>
          <iyz>0</iyz>
          <izz>0.13144</izz>
        </inertia>
      </inertial>
      <collision name='base_collision'>
        <pose>0 0 0 0 -0 0</pose>
        <geometry>
          <box>
            <size>0.7 0.3 0.2</size>
          </box>
        </geometry>
      </collision>
      <visual name='base_visual'>
        <pose>0 0 0 0 -0 0</pose>
        <geometry>
          <mesh>
            <scale>1 1 1</scale>
            <uri>file:///home/kuba/fun/ros/spot/src/spot/spot_description/meshes/visual/body.dae</uri>
          </mesh>
        </geometry>
      </visual>
    </link>
    <joint name='LF_HAA' type='revolute'>
      <pose relative_to='base'>0.29785 0.055 0 0 -0 0</pose>
      <parent>base</parent>
      <child>fl_hip</child>
      <axis>
        <xyz>1 0 0</xyz>
        <limit>
          <lower>-10.7854</lower>
          <upper>10.7854</upper>
          <effort>1000</effort>
          <velocity>1000</velocity>
        </limit>
        <dynamics>
          <spring_reference>0</spring_reference>
          <spring_stiffness>0</spring_stiffness>
        </dynamics>
      </axis>
    </joint>
    <link name='fl_hip'>
      <pose relative_to='LF_HAA'>0 0 0 0 -0 0</pose>
      <inertial>
        <pose>-0.005374 0.012842 9.9e-05 -0.716521 0.029565 0.036552</pose>
        <mass>1.68</mass>
        <inertia>
          <ixx>0.00211474</ixx>
          <ixy>0</ixy>
          <ixz>0</ixz>
          <iyy>0.00181296</iyy>
          <iyz>0</iyz>
          <izz>0.00226544</izz>
        </inertia>
      </inertial>
      <visual name='fl_hip_visual'>
        <pose>0 0 0 0 -0 0</pose>
        <geometry>
          <mesh>
            <scale>1 1 1</scale>
            <uri>file:///home/kuba/fun/ros/spot/src/spot/spot_description/meshes/visual/fl_hip.dae</uri>
          </mesh>
        </geometry>
      </visual>
    </link>
    <joint name='LF_HFE' type='revolute'>
      <pose relative_to='fl_hip'>0 0.1108 0 0 -0 0</pose>
      <parent>fl_hip</parent>
      <child>fl_uleg</child>
      <axis>
        <xyz>0 1 0</xyz>
        <limit>
          <lower>-10.8988</lower>
          <upper>12.2951</upper>
          <effort>1000</effort>
          <velocity>1000</velocity>
        </limit>
        <dynamics>
          <spring_reference>0</spring_reference>
          <spring_stiffness>0</spring_stiffness>
        </dynamics>
      </axis>
    </joint>
    <link name='fl_uleg'>
      <pose relative_to='LF_HFE'>0 0 0 0 -0 0</pose>
      <inertial>
        <pose>0.005142 -0.002432 -0.121009 -0.264378 -0.048532 0.024047</pose>
        <mass>2.34</mass>
        <inertia>
          <ixx>0.0275596</ixx>
          <ixy>0</ixy>
          <ixz>0</ixz>
          <iyy>0.0273549</iyy>
          <iyz>0</iyz>
          <izz>0.00284815</izz>
        </inertia>
      </inertial>
      <visual name='fl_uleg_visual'>
        <pose>0 0 0 0 -0 0</pose>
        <geometry>
          <mesh>
            <scale>1 1 1</scale>
            <uri>file:///home/kuba/fun/ros/spot/src/spot/spot_description/meshes/visual/fl_uleg.dae</uri>
          </mesh>
        </geometry>
      </visual>
    </link>
    <joint name='LF_KFE' type='revolute'>
      <pose relative_to='fl_uleg'>0.025 0 -0.32 0 -0 0</pose>
      <parent>fl_uleg</parent>
      <child>fl_lleg</child>
      <axis>
        <xyz>0 1 0</xyz>
        <limit>
          <lower>-12.7929</lower>
          <upper>12.7929</upper>
          <effort>1000</effort>
          <velocity>1000</velocity>
        </limit>
        <dynamics>
          <spring_reference>0</spring_reference>
          <spring_stiffness>0</spring_stiffness>
        </dynamics>
      </axis>
    </joint>
    <link name='fl_lleg'>
      <pose relative_to='LF_KFE'>0 0 0 0 -0 0</pose>
      <inertial>
        <pose>0.002258 4.6e-05 -0.180082 -0.007267 -0.009592 0.000353</pose>
        <mass>0.35</mass>
        <inertia>
          <ixx>0.00399902</ixx>
          <ixy>0</ixy>
          <ixz>0</ixz>
          <iyy>0.00405032</iyy>
          <iyz>0</iyz>
          <izz>0.00014934</izz>
        </inertia>
      </inertial>
      <collision name='fl_lleg_fixed_joint_lump__LF_FOOT_collision_sensor_collision'>
        <pose>0 0 -0.335 0 -0 0</pose>
        <geometry>
          <sphere>
            <radius>0.035</radius>
          </sphere>
        </geometry>
        <surface>
          <contact>
            <ode>
              <kp>1e+06</kp>
              <kd>1</kd>
            </ode>
          </contact>
          <friction>
            <ode>
              <mu>1.85</mu>
              <mu2>1.85</mu2>
            </ode>
          </friction>
        </surface>
      </collision>
      <visual name='fl_lleg_visual'>
        <pose>0 0 0 0 -0 0</pose>
        <geometry>
          <mesh>
            <scale>1 1 1</scale>
            <uri>file:///home/kuba/fun/ros/spot/src/spot/spot_description/meshes/visual/fl_lleg.dae</uri>
          </mesh>
        </geometry>
      </visual>
      <sensor name='lf_foot_contact' type='contact'>
        <plugin name='lf_contact_plugin' filename='libContactSensor.so'/>
        <contact>
          <collision>fl_lleg_fixed_joint_lump__LF_FOOT_collision_sensor_collision</collision>
          <topic>__default_topic__</topic>
        </contact>
        <pose>0 0 -0.335 0 -0 0</pose>
      </sensor>
    </link>
    <joint name='LH_HAA' type='revolute'>
      <pose relative_to='base'>-0.29785 0.055 0 0 -0 0</pose>
      <parent>base</parent>
      <child>hl_hip</child>
      <axis>
        <xyz>1 0 0</xyz>
        <limit>
          <lower>-10.7854</lower>
          <upper>10.7854</upper>
          <effort>1000</effort>
          <velocity>1000</velocity>
        </limit>
        <dynamics>
          <spring_reference>0</spring_reference>
          <spring_stiffness>0</spring_stiffness>
        </dynamics>
      </axis>
    </joint>
    <link name='hl_hip'>
      <pose relative_to='LH_HAA'>0 0 0 0 -0 0</pose>
      <inertial>
        <pose>0.005374 0.012842 -9.9e-05 0.716521 0.029565 -0.036552</pose>
        <mass>1.68</mass>
        <inertia>
          <ixx>0.00211474</ixx>
          <ixy>0</ixy>
          <ixz>0</ixz>
          <iyy>0.00181296</iyy>
          <iyz>0</iyz>
          <izz>0.00226544</izz>
        </inertia>
      </inertial>
      <visual name='hl_hip_visual'>
        <pose>0 0 0 0 -0 0</pose>
        <geometry>
          <mesh>
            <scale>1 1 1</scale>
            <uri>file:///home/kuba/fun/ros/spot/src/spot/spot_description/meshes/visual/hl_hip.dae</uri>
          </mesh>
        </geometry>
      </visual>
    </link>
    <joint name='LH_HFE' type='revolute'>
      <pose relative_to='hl_hip'>0 0.1108 0 0 -0 0</pose>
      <parent>hl_hip</parent>
      <child>hl_uleg</child>
      <axis>
        <xyz>0 1 0</xyz>
        <limit>
          <lower>-10.8988</lower>
          <upper>12.2951</upper>
          <effort>1000</effort>
          <velocity>1000</velocity>
        </limit>
        <dynamics>
          <spring_reference>0</spring_reference>
          <spring_stiffness>0</spring_stiffness>
        </dynamics>
      </axis>
    </joint>
    <link name='hl_uleg'>
      <pose relative_to='LH_HFE'>0 0 0 0 -0 0</pose>
      <inertial>
        <pose>0.005142 -0.002432 -0.121009 -0.264378 -0.048532 0.024047</pose>
        <mass>2.34</mass>
        <inertia>
          <ixx>0.0275596</ixx>
          <ixy>0</ixy>
          <ixz>0</ixz>
          <iyy>0.0273549</iyy>
          <iyz>0</iyz>
          <izz>0.00284815</izz>
        </inertia>
      </inertial>
      <visual name='hl_uleg_visual'>
        <pose>0 0 0 0 -0 0</pose>
        <geometry>
          <mesh>
            <scale>1 1 1</scale>
            <uri>file:///home/kuba/fun/ros/spot/src/spot/spot_description/meshes/visual/hl_uleg.dae</uri>
          </mesh>
        </geometry>
      </visual>
    </link>
    <joint name='LH_KFE' type='revolute'>
      <pose relative_to='hl_uleg'>0.025 0 -0.32 0 -0 0</pose>
      <parent>hl_uleg</parent>
      <child>hl_lleg</child>
      <axis>
        <xyz>0 1 0</xyz>
        <limit>
          <lower>-12.7929</lower>
          <upper>12.7929</upper>
          <effort>1000</effort>
          <velocity>1000</velocity>
        </limit>
        <dynamics>
          <spring_reference>0</spring_reference>
          <spring_stiffness>0</spring_stiffness>
        </dynamics>
      </axis>
    </joint>
    <link name='hl_lleg'>
      <pose relative_to='LH_KFE'>0 0 0 0 -0 0</pose>
      <inertial>
        <pose>0.002258 4.6e-05 -0.180082 -0.007267 -0.009592 0.000353</pose>
        <mass>0.35</mass>
        <inertia>
          <ixx>0.00399902</ixx>
          <ixy>0</ixy>
          <ixz>0</ixz>
          <iyy>0.00405032</iyy>
          <iyz>0</iyz>
          <izz>0.00014934</izz>
        </inertia>
      </inertial>
      <collision name='hl_lleg_fixed_joint_lump__LH_FOOT_collision_sensor_collision'>
        <pose>0 0 -0.335 0 -0 0</pose>
        <geometry>
          <sphere>
            <radius>0.035</radius>
          </sphere>
        </geometry>
        <surface>
          <contact>
            <ode>
              <kp>1e+06</kp>
              <kd>1</kd>
            </ode>
          </contact>
          <friction>
            <ode>
              <mu>1.85</mu>
              <mu2>1.85</mu2>
            </ode>
          </friction>
        </surface>
      </collision>
      <visual name='hl_lleg_visual'>
        <pose>0 0 0 0 -0 0</pose>
        <geometry>
          <mesh>
            <scale>1 1 1</scale>
            <uri>file:///home/kuba/fun/ros/spot/src/spot/spot_description/meshes/visual/hl_lleg.dae</uri>
          </mesh>
        </geometry>
      </visual>
      <sensor name='lh_foot_contact' type='contact'>
        <plugin name='lh_contact_plugin' filename='libContactSensor.so'/>
        <contact>
          <collision>hl_lleg_fixed_joint_lump__LH_FOOT_collision_sensor_collision</collision>
          <topic>__default_topic__</topic>
        </contact>
        <pose>0 0 -0.335 0 -0 0</pose>
      </sensor>
    </link>
    <joint name='RF_HAA' type='revolute'>
      <pose relative_to='base'>0.29785 -0.055 0 0 -0 0</pose>
      <parent>base</parent>
      <child>fr_hip</child>
      <axis>
        <xyz>1 0 0</xyz>
        <limit>
          <lower>-10.7854</lower>
          <upper>10.7854</upper>
          <effort>1000</effort>
          <velocity>1000</velocity>
        </limit>
        <dynamics>
          <spring_reference>0</spring_reference>
          <spring_stiffness>0</spring_stiffness>
        </dynamics>
      </axis>
    </joint>
    <link name='fr_hip'>
      <pose relative_to='RF_HAA'>0 0 0 0 -0 0</pose>
      <inertial>
        <pose>-0.005374 -0.012842 -9.9e-05 0.716521 -0.029565 0.036552</pose>
        <mass>1.68</mass>
        <inertia>
          <ixx>0.00211474</ixx>
          <ixy>0</ixy>
          <ixz>0</ixz>
          <iyy>0.00181296</iyy>
          <iyz>0</iyz>
          <izz>0.00226544</izz>
        </inertia>
      </inertial>
      <visual name='fr_hip_visual'>
        <pose>0 0 0 0 -0 0</pose>
        <geometry>
          <mesh>
            <scale>1 1 1</scale>
            <uri>file:///home/kuba/fun/ros/spot/src/spot/spot_description/meshes/visual/fr_hip.dae</uri>
          </mesh>
        </geometry>
      </visual>
    </link>
    <joint name='RF_HFE' type='revolute'>
      <pose relative_to='fr_hip'>0 -0.1108 0 0 -0 0</pose>
      <parent>fr_hip</parent>
      <child>fr_uleg</child>
      <axis>
        <xyz>0 1 0</xyz>
        <limit>
          <lower>-10.8988</lower>
          <upper>12.2436</upper>
          <effort>1000</effort>
          <velocity>1000</velocity>
        </limit>
        <dynamics>
          <spring_reference>0</spring_reference>
          <spring_stiffness>0</spring_stiffness>
        </dynamics>
      </axis>
    </joint>
    <link name='fr_uleg'>
      <pose relative_to='RF_HFE'>0 0 0 0 -0 0</pose>
      <inertial>
        <pose>0.005142 0.002432 -0.121009 0.264391 -0.048532 -0.024047</pose>
        <mass>2.34</mass>
        <inertia>
          <ixx>0.0275596</ixx>
          <ixy>0</ixy>
          <ixz>0</ixz>
          <iyy>0.0273549</iyy>
          <iyz>0</iyz>
          <izz>0.00284815</izz>
        </inertia>
      </inertial>
      <visual name='fr_uleg_visual'>
        <pose>0 0 0 0 -0 0</pose>
        <geometry>
          <mesh>
            <scale>1 1 1</scale>
            <uri>file:///home/kuba/fun/ros/spot/src/spot/spot_description/meshes/visual/fr_uleg.dae</uri>
          </mesh>
        </geometry>
      </visual>
    </link>
    <joint name='RF_KFE' type='revolute'>
      <pose relative_to='fr_uleg'>0.025 0 -0.32 0 -0 0</pose>
      <parent>fr_uleg</parent>
      <child>fr_lleg</child>
      <axis>
        <xyz>0 1 0</xyz>
        <limit>
          <lower>-12.7929</lower>
          <upper>12.7929</upper>
          <effort>1000</effort>
          <velocity>1000</velocity>
        </limit>
        <dynamics>
          <spring_reference>0</spring_reference>
          <spring_stiffness>0</spring_stiffness>
        </dynamics>
      </axis>
    </joint>
    <link name='fr_lleg'>
      <pose relative_to='RF_KFE'>0 0 0 0 -0 0</pose>
      <inertial>
        <pose>0.002258 4.6e-05 -0.180082 -0.007267 -0.009592 0.000353</pose>
        <mass>0.35</mass>
        <inertia>
          <ixx>0.00399902</ixx>
          <ixy>0</ixy>
          <ixz>0</ixz>
          <iyy>0.00405032</iyy>
          <iyz>0</iyz>
          <izz>0.00014934</izz>
        </inertia>
      </inertial>
      <collision name='fr_lleg_fixed_joint_lump__RF_FOOT_collision_sensor_collision'>
        <pose>0 0 -0.335 0 -0 0</pose>
        <geometry>
          <sphere>
            <radius>0.035</radius>
          </sphere>
        </geometry>
        <surface>
          <contact>
            <ode>
              <kp>1e+06</kp>
              <kd>1</kd>
            </ode>
          </contact>
          <friction>
            <ode>
              <mu>1.85</mu>
              <mu2>1.85</mu2>
            </ode>
          </friction>
        </surface>
      </collision>
      <visual name='fr_lleg_visual'>
        <pose>0 0 0 0 -0 0</pose>
        <geometry>
          <mesh>
            <scale>1 1 1</scale>
            <uri>file:///home/kuba/fun/ros/spot/src/spot/spot_description/meshes/visual/fr_lleg.dae</uri>
          </mesh>
        </geometry>
      </visual>
      <sensor name='rf_foot_contact' type='contact'>
        <plugin name='rf_contact_plugin' filename='libContactSensor.so'/>
        <contact>
          <collision>fr_lleg_fixed_joint_lump__RF_FOOT_collision_sensor_collision</collision>
          <topic>__default_topic__</topic>
        </contact>
        <pose>0 0 -0.335 0 -0 0</pose>
      </sensor>
    </link>
    <joint name='RH_HAA' type='revolute'>
      <pose relative_to='base'>-0.29785 -0.055 0 0 -0 0</pose>
      <parent>base</parent>
      <child>hr_hip</child>
      <axis>
        <xyz>1 0 0</xyz>
        <limit>
          <lower>-10.7854</lower>
          <upper>10.7854</upper>
          <effort>1000</effort>
          <velocity>1000</velocity>
        </limit>
        <dynamics>
          <spring_reference>0</spring_reference>
          <spring_stiffness>0</spring_stiffness>
        </dynamics>
      </axis>
    </joint>
    <link name='hr_hip'>
      <pose relative_to='RH_HAA'>0 0 0 0 -0 0</pose>
      <inertial>
        <pose>0.005374 -0.012842 9.9e-05 -0.716521 -0.029565 -0.036552</pose>
        <mass>1.68</mass>
        <inertia>
          <ixx>0.00211474</ixx>
          <ixy>0</ixy>
          <ixz>0</ixz>
          <iyy>0.00181296</iyy>
          <iyz>0</iyz>
          <izz>0.00226544</izz>
        </inertia>
      </inertial>
      <visual name='hr_hip_visual'>
        <pose>0 0 0 0 -0 0</pose>
        <geometry>
          <mesh>
            <scale>1 1 1</scale>
            <uri>file:///home/kuba/fun/ros/spot/src/spot/spot_description/meshes/visual/hr_hip.dae</uri>
          </mesh>
        </geometry>
      </visual>
    </link>
    <joint name='RH_HFE' type='revolute'>
      <pose relative_to='hr_hip'>0 -0.1108 0 0 -0 0</pose>
      <parent>hr_hip</parent>
      <child>hr_uleg</child>
      <axis>
        <xyz>0 1 0</xyz>
        <limit>
          <lower>-10.8988</lower>
          <upper>12.2951</upper>
          <effort>1000</effort>
          <velocity>1000</velocity>
        </limit>
        <dynamics>
          <spring_reference>0</spring_reference>
          <spring_stiffness>0</spring_stiffness>
        </dynamics>
      </axis>
    </joint>
    <link name='hr_uleg'>
      <pose relative_to='RH_HFE'>0 0 0 0 -0 0</pose>
      <inertial>
        <pose>0.005142 0.002432 -0.121009 0.264391 -0.048532 -0.024047</pose>
        <mass>2.34</mass>
        <inertia>
          <ixx>0.0275596</ixx>
          <ixy>0</ixy>
          <ixz>0</ixz>
          <iyy>0.0273549</iyy>
          <iyz>0</iyz>
          <izz>0.00284815</izz>
        </inertia>
      </inertial>
      <visual name='hr_uleg_visual'>
        <pose>0 0 0 0 -0 0</pose>
        <geometry>
          <mesh>
            <scale>1 1 1</scale>
            <uri>file:///home/kuba/fun/ros/spot/src/spot/spot_description/meshes/visual/hr_uleg.dae</uri>
          </mesh>
        </geometry>
      </visual>
    </link>
    <joint name='RH_KFE' type='revolute'>
      <pose relative_to='hr_uleg'>0.025 0 -0.32 0 -0 0</pose>
      <parent>hr_uleg</parent>
      <child>hr_lleg</child>
      <axis>
        <xyz>0 1 0</xyz>
        <limit>
          <lower>-12.7929</lower>
          <upper>12.7929</upper>
          <effort>1000</effort>
          <velocity>1000</velocity>
        </limit>
        <dynamics>
          <spring_reference>0</spring_reference>
          <spring_stiffness>0</spring_stiffness>
        </dynamics>
      </axis>
    </joint>
    <link name='hr_lleg'>
      <pose relative_to='RH_KFE'>0 0 0 0 -0 0</pose>
      <inertial>
        <pose>0.002258 4.6e-05 -0.180082 -0.007267 -0.009592 0.000353</pose>
        <mass>0.35</mass>
        <inertia>
          <ixx>0.00399902</ixx>
          <ixy>0</ixy>
          <ixz>0</ixz>
          <iyy>0.00405032</iyy>
          <iyz>0</iyz>
          <izz>0.00014934</izz>
        </inertia>
      </inertial>
      <collision name='hr_lleg_fixed_joint_lump__RH_FOOT_collision_sensor_collision'>
        <pose>0 0 -0.335 0 -0 0</pose>
        <geometry>
          <sphere>
            <radius>0.035</radius>
          </sphere>
        </geometry>
        <surface>
          <contact>
            <ode>
              <kp>1e+06</kp>
              <kd>1</kd>
            </ode>
          </contact>
          <friction>
            <ode>
              <mu>1.85</mu>
              <mu2>1.85</mu2>
            </ode>
          </friction>
        </surface>
      </collision>
      <visual name='hr_lleg_visual'>
        <pose>0 0 0 0 -0 0</pose>
        <geometry>
          <mesh>
            <scale>1 1 1</scale>
            <uri>file:///home/kuba/fun/ros/spot/src/spot/spot_description/meshes/visual/hr_lleg.dae</uri>
          </mesh>
        </geometry>
      </visual>
      <sensor name='rh_foot_contact' type='contact'>
        <plugin name='rh_contact_plugin' filename='libContactSensor.so'/>
        <contact>
          <collision>hr_lleg_fixed_joint_lump__RH_FOOT_collision_sensor_collision</collision>
          <topic>__default_topic__</topic>
        </contact>
        <pose>0 0 -0.335 0 -0 0</pose>
      </sensor>
    </link>
    <static>0</static>
    <plugin name='gazebo_ros_control' filename='libgazebo_ros_control.so'>
      <robotSimType>gazebo_ros_control/DefaultRobotHWSim</robotSimType>
      <robotNamespace>/anymal</robotNamespace>
    </plugin>
    <plugin name='StateEstimator' filename='libStateEstimator.so'/>
  </model>
</sdf>
